ERROR 2023-10-31 10:09:01,777 services Authentication failed due to: HTTPConnectionPool(host='authentication-service', port=8443): Max retries exceeded with url: /api/user-management/user-info/ (Caused by NameResolutionError("<urllib3.connection.HTTPConnection object at 0x000001B85A1A3D10>: Failed to resolve 'authentication-service' ([Errno 11001] getaddrinfo failed)"))
ERROR 2023-10-31 10:09:23,471 services Authentication failed due to: HTTPConnectionPool(host='authentication-service', port=8443): Max retries exceeded with url: /api/user-management/user-info/ (Caused by NameResolutionError("<urllib3.connection.HTTPConnection object at 0x000001B85A2FCB10>: Failed to resolve 'authentication-service' ([Errno 11001] getaddrinfo failed)"))
ERROR 2023-10-31 02:47:06,238 services Authentication failed due to: 401 Client Error: Unauthorized for url: http://authentication-service:8443/api/user-management/user-info/
ERROR 2023-10-31 03:22:00,088 services Authentication failed due to: HTTPConnectionPool(host='authentication-service', port=8443): Max retries exceeded with url: /api/user-management/user-info/ (Caused by NewConnectionError('<urllib3.connection.HTTPConnection object at 0x7f858dc8d610>: Failed to establish a new connection: [Errno 111] Connection refused'))
ERROR 2023-10-31 03:22:40,309 services Authentication failed due to: 401 Client Error: Unauthorized for url: http://authentication-service:8443/api/user-management/user-info/
ERROR 2023-10-31 03:23:16,889 log Internal Server Error: /api/telemetry/add-telemetry/
Traceback (most recent call last):
  File "/usr/local/lib/python3.11/site-packages/django/db/backends/utils.py", line 89, in _execute
    return self.cursor.execute(sql, params)
           ^^^^^^^^^^^^^^^^^^^^^^^^^^^^^^^^
  File "/usr/local/lib/python3.11/site-packages/django/db/backends/sqlite3/base.py", line 328, in execute
    return super().execute(query, params)
           ^^^^^^^^^^^^^^^^^^^^^^^^^^^^^^
sqlite3.OperationalError: table telemetry_telemetry has no column named rocket_name

The above exception was the direct cause of the following exception:

Traceback (most recent call last):
  File "/usr/local/lib/python3.11/site-packages/asgiref/sync.py", line 534, in thread_handler
    raise exc_info[1]
  File "/usr/local/lib/python3.11/site-packages/django/core/handlers/exception.py", line 42, in inner
    response = await get_response(request)
               ^^^^^^^^^^^^^^^^^^^^^^^^^^^
  File "/usr/local/lib/python3.11/site-packages/asgiref/sync.py", line 534, in thread_handler
    raise exc_info[1]
  File "/usr/local/lib/python3.11/site-packages/django/core/handlers/base.py", line 253, in _get_response_async
    response = await wrapped_callback(
               ^^^^^^^^^^^^^^^^^^^^^^^
  File "/usr/local/lib/python3.11/site-packages/asgiref/sync.py", line 479, in __call__
    ret: _R = await loop.run_in_executor(
              ^^^^^^^^^^^^^^^^^^^^^^^^^^^
  File "/usr/local/lib/python3.11/concurrent/futures/thread.py", line 58, in run
    result = self.fn(*self.args, **self.kwargs)
             ^^^^^^^^^^^^^^^^^^^^^^^^^^^^^^^^^^
  File "/usr/local/lib/python3.11/site-packages/asgiref/sync.py", line 538, in thread_handler
    return func(*args, **kwargs)
           ^^^^^^^^^^^^^^^^^^^^^
  File "/usr/local/lib/python3.11/site-packages/django/views/decorators/csrf.py", line 56, in wrapper_view
    return view_func(*args, **kwargs)
           ^^^^^^^^^^^^^^^^^^^^^^^^^^
  File "/usr/local/lib/python3.11/site-packages/django/views/generic/base.py", line 104, in view
    return self.dispatch(request, *args, **kwargs)
           ^^^^^^^^^^^^^^^^^^^^^^^^^^^^^^^^^^^^^^^
  File "/usr/local/lib/python3.11/site-packages/rest_framework/views.py", line 509, in dispatch
    response = self.handle_exception(exc)
               ^^^^^^^^^^^^^^^^^^^^^^^^^^
  File "/usr/local/lib/python3.11/site-packages/rest_framework/views.py", line 469, in handle_exception
    self.raise_uncaught_exception(exc)
  File "/usr/local/lib/python3.11/site-packages/rest_framework/views.py", line 480, in raise_uncaught_exception
    raise exc
  File "/usr/local/lib/python3.11/site-packages/rest_framework/views.py", line 506, in dispatch
    response = handler(request, *args, **kwargs)
               ^^^^^^^^^^^^^^^^^^^^^^^^^^^^^^^^^
  File "/app/apps/telemetry/views.py", line 42, in post
    ).save()
      ^^^^^^
  File "/app/apps/telemetry/models.py", line 45, in save
    super().save(*args, **kwargs)
  File "/usr/local/lib/python3.11/site-packages/django/db/models/base.py", line 814, in save
    self.save_base(
  File "/usr/local/lib/python3.11/site-packages/django/db/models/base.py", line 877, in save_base
    updated = self._save_table(
              ^^^^^^^^^^^^^^^^^
  File "/usr/local/lib/python3.11/site-packages/django/db/models/base.py", line 1020, in _save_table
    results = self._do_insert(
              ^^^^^^^^^^^^^^^^
  File "/usr/local/lib/python3.11/site-packages/django/db/models/base.py", line 1061, in _do_insert
    return manager._insert(
           ^^^^^^^^^^^^^^^^
  File "/usr/local/lib/python3.11/site-packages/django/db/models/manager.py", line 87, in manager_method
    return getattr(self.get_queryset(), name)(*args, **kwargs)
           ^^^^^^^^^^^^^^^^^^^^^^^^^^^^^^^^^^^^^^^^^^^^^^^^^^^
  File "/usr/local/lib/python3.11/site-packages/django/db/models/query.py", line 1805, in _insert
    return query.get_compiler(using=using).execute_sql(returning_fields)
           ^^^^^^^^^^^^^^^^^^^^^^^^^^^^^^^^^^^^^^^^^^^^^^^^^^^^^^^^^^^^^
  File "/usr/local/lib/python3.11/site-packages/django/db/models/sql/compiler.py", line 1822, in execute_sql
    cursor.execute(sql, params)
  File "/usr/local/lib/python3.11/site-packages/django/db/backends/utils.py", line 102, in execute
    return super().execute(sql, params)
           ^^^^^^^^^^^^^^^^^^^^^^^^^^^^
  File "/usr/local/lib/python3.11/site-packages/django/db/backends/utils.py", line 67, in execute
    return self._execute_with_wrappers(
           ^^^^^^^^^^^^^^^^^^^^^^^^^^^^
  File "/usr/local/lib/python3.11/site-packages/django/db/backends/utils.py", line 80, in _execute_with_wrappers
    return executor(sql, params, many, context)
           ^^^^^^^^^^^^^^^^^^^^^^^^^^^^^^^^^^^^
  File "/usr/local/lib/python3.11/site-packages/django/db/backends/utils.py", line 84, in _execute
    with self.db.wrap_database_errors:
  File "/usr/local/lib/python3.11/site-packages/django/db/utils.py", line 91, in __exit__
    raise dj_exc_value.with_traceback(traceback) from exc_value
  File "/usr/local/lib/python3.11/site-packages/django/db/backends/utils.py", line 89, in _execute
    return self.cursor.execute(sql, params)
           ^^^^^^^^^^^^^^^^^^^^^^^^^^^^^^^^
  File "/usr/local/lib/python3.11/site-packages/django/db/backends/sqlite3/base.py", line 328, in execute
    return super().execute(query, params)
           ^^^^^^^^^^^^^^^^^^^^^^^^^^^^^^
django.db.utils.OperationalError: table telemetry_telemetry has no column named rocket_name
ERROR 2023-10-31 11:26:46,339 log Internal Server Error: /api/telemetry/add-telemetry/
Traceback (most recent call last):
  File "C:\Users\maxma\Documents\Learning\Projects\rocket_lab\command_center\api\telemetry_service\venv\Lib\site-packages\django\db\backends\utils.py", line 89, in _execute
    return self.cursor.execute(sql, params)
           ^^^^^^^^^^^^^^^^^^^^^^^^^^^^^^^^
  File "C:\Users\maxma\Documents\Learning\Projects\rocket_lab\command_center\api\telemetry_service\venv\Lib\site-packages\django\db\backends\sqlite3\base.py", line 328, in execute
    return super().execute(query, params)
           ^^^^^^^^^^^^^^^^^^^^^^^^^^^^^^
sqlite3.OperationalError: table telemetry_telemetry has no column named rocket_name

The above exception was the direct cause of the following exception:

Traceback (most recent call last):
  File "C:\Users\maxma\Documents\Learning\Projects\rocket_lab\command_center\api\telemetry_service\venv\Lib\site-packages\django\core\handlers\exception.py", line 55, in inner
    response = get_response(request)
               ^^^^^^^^^^^^^^^^^^^^^
  File "C:\Users\maxma\Documents\Learning\Projects\rocket_lab\command_center\api\telemetry_service\venv\Lib\site-packages\django\core\handlers\base.py", line 197, in _get_response
    response = wrapped_callback(request, *callback_args, **callback_kwargs)
               ^^^^^^^^^^^^^^^^^^^^^^^^^^^^^^^^^^^^^^^^^^^^^^^^^^^^^^^^^^^^
  File "C:\Users\maxma\Documents\Learning\Projects\rocket_lab\command_center\api\telemetry_service\venv\Lib\site-packages\django\views\decorators\csrf.py", line 56, in wrapper_view
    return view_func(*args, **kwargs)
           ^^^^^^^^^^^^^^^^^^^^^^^^^^
  File "C:\Users\maxma\Documents\Learning\Projects\rocket_lab\command_center\api\telemetry_service\venv\Lib\site-packages\django\views\generic\base.py", line 104, in view
    return self.dispatch(request, *args, **kwargs)
           ^^^^^^^^^^^^^^^^^^^^^^^^^^^^^^^^^^^^^^^
  File "C:\Users\maxma\Documents\Learning\Projects\rocket_lab\command_center\api\telemetry_service\venv\Lib\site-packages\rest_framework\views.py", line 509, in dispatch
    response = self.handle_exception(exc)
               ^^^^^^^^^^^^^^^^^^^^^^^^^^
  File "C:\Users\maxma\Documents\Learning\Projects\rocket_lab\command_center\api\telemetry_service\venv\Lib\site-packages\rest_framework\views.py", line 469, in handle_exception
    self.raise_uncaught_exception(exc)
  File "C:\Users\maxma\Documents\Learning\Projects\rocket_lab\command_center\api\telemetry_service\venv\Lib\site-packages\rest_framework\views.py", line 480, in raise_uncaught_exception
    raise exc
  File "C:\Users\maxma\Documents\Learning\Projects\rocket_lab\command_center\api\telemetry_service\venv\Lib\site-packages\rest_framework\views.py", line 506, in dispatch
    response = handler(request, *args, **kwargs)
               ^^^^^^^^^^^^^^^^^^^^^^^^^^^^^^^^^
  File "C:\Users\maxma\Documents\Learning\Projects\rocket_lab\command_center\api\telemetry_service\apps\telemetry\views.py", line 42, in post
    ).save()
      ^^^^^^
  File "C:\Users\maxma\Documents\Learning\Projects\rocket_lab\command_center\api\telemetry_service\apps\telemetry\models.py", line 45, in save
    super().save(*args, **kwargs)
  File "C:\Users\maxma\Documents\Learning\Projects\rocket_lab\command_center\api\telemetry_service\venv\Lib\site-packages\django\db\models\base.py", line 814, in save
    self.save_base(
  File "C:\Users\maxma\Documents\Learning\Projects\rocket_lab\command_center\api\telemetry_service\venv\Lib\site-packages\django\db\models\base.py", line 877, in save_base
    updated = self._save_table(
              ^^^^^^^^^^^^^^^^^
  File "C:\Users\maxma\Documents\Learning\Projects\rocket_lab\command_center\api\telemetry_service\venv\Lib\site-packages\django\db\models\base.py", line 1020, in _save_table
    results = self._do_insert(
              ^^^^^^^^^^^^^^^^
  File "C:\Users\maxma\Documents\Learning\Projects\rocket_lab\command_center\api\telemetry_service\venv\Lib\site-packages\django\db\models\base.py", line 1061, in _do_insert
    return manager._insert(
           ^^^^^^^^^^^^^^^^
  File "C:\Users\maxma\Documents\Learning\Projects\rocket_lab\command_center\api\telemetry_service\venv\Lib\site-packages\django\db\models\manager.py", line 87, in manager_method
    return getattr(self.get_queryset(), name)(*args, **kwargs)
           ^^^^^^^^^^^^^^^^^^^^^^^^^^^^^^^^^^^^^^^^^^^^^^^^^^^
  File "C:\Users\maxma\Documents\Learning\Projects\rocket_lab\command_center\api\telemetry_service\venv\Lib\site-packages\django\db\models\query.py", line 1805, in _insert
    return query.get_compiler(using=using).execute_sql(returning_fields)
           ^^^^^^^^^^^^^^^^^^^^^^^^^^^^^^^^^^^^^^^^^^^^^^^^^^^^^^^^^^^^^
  File "C:\Users\maxma\Documents\Learning\Projects\rocket_lab\command_center\api\telemetry_service\venv\Lib\site-packages\django\db\models\sql\compiler.py", line 1822, in execute_sql
    cursor.execute(sql, params)
  File "C:\Users\maxma\Documents\Learning\Projects\rocket_lab\command_center\api\telemetry_service\venv\Lib\site-packages\django\db\backends\utils.py", line 102, in execute
    return super().execute(sql, params)
           ^^^^^^^^^^^^^^^^^^^^^^^^^^^^
  File "C:\Users\maxma\Documents\Learning\Projects\rocket_lab\command_center\api\telemetry_service\venv\Lib\site-packages\django\db\backends\utils.py", line 67, in execute
    return self._execute_with_wrappers(
           ^^^^^^^^^^^^^^^^^^^^^^^^^^^^
  File "C:\Users\maxma\Documents\Learning\Projects\rocket_lab\command_center\api\telemetry_service\venv\Lib\site-packages\django\db\backends\utils.py", line 80, in _execute_with_wrappers
    return executor(sql, params, many, context)
           ^^^^^^^^^^^^^^^^^^^^^^^^^^^^^^^^^^^^
  File "C:\Users\maxma\Documents\Learning\Projects\rocket_lab\command_center\api\telemetry_service\venv\Lib\site-packages\django\db\backends\utils.py", line 84, in _execute
    with self.db.wrap_database_errors:
  File "C:\Users\maxma\Documents\Learning\Projects\rocket_lab\command_center\api\telemetry_service\venv\Lib\site-packages\django\db\utils.py", line 91, in __exit__
    raise dj_exc_value.with_traceback(traceback) from exc_value
  File "C:\Users\maxma\Documents\Learning\Projects\rocket_lab\command_center\api\telemetry_service\venv\Lib\site-packages\django\db\backends\utils.py", line 89, in _execute
    return self.cursor.execute(sql, params)
           ^^^^^^^^^^^^^^^^^^^^^^^^^^^^^^^^
  File "C:\Users\maxma\Documents\Learning\Projects\rocket_lab\command_center\api\telemetry_service\venv\Lib\site-packages\django\db\backends\sqlite3\base.py", line 328, in execute
    return super().execute(query, params)
           ^^^^^^^^^^^^^^^^^^^^^^^^^^^^^^
django.db.utils.OperationalError: table telemetry_telemetry has no column named rocket_name
ERROR 2023-10-31 11:26:46,356 basehttp "POST /api/telemetry/add-telemetry/ HTTP/1.1" 500 199206
ERROR 2023-10-31 03:32:46,641 services Authentication failed due to: HTTPConnectionPool(host='authentication-service', port=8443): Max retries exceeded with url: /api/user-management/user-info/ (Caused by NewConnectionError('<urllib3.connection.HTTPConnection object at 0x7f8bb4596810>: Failed to establish a new connection: [Errno 111] Connection refused'))
ERROR 2023-10-31 03:50:00,741 services Authentication failed due to: 401 Client Error: Unauthorized for url: http://authentication-service:8443/api/user-management/user-info/
ERROR 2023-10-31 03:50:12,338 services Authentication failed due to: 401 Client Error: Unauthorized for url: http://authentication-service:8443/api/user-management/user-info/
ERROR 2023-10-31 05:36:20,566 services Authentication failed due to: 401 Client Error: Unauthorized for url: http://authentication-service:8443/api/user-management/user-info/
ERROR 2023-10-31 05:37:22,546 services Authentication failed due to: 401 Client Error: Unauthorized for url: http://authentication-service:8443/api/user-management/user-info/
ERROR 2023-11-01 02:02:45,482 services Authentication failed due to: 401 Client Error: Unauthorized for url: http://authentication-service:8443/api/user-management/user-info/
ERROR 2023-11-01 02:03:25,317 services Authentication failed due to: 401 Client Error: Unauthorized for url: http://authentication-service:8443/api/user-management/user-info/
ERROR 2023-11-01 02:03:53,991 services Authentication failed due to: 401 Client Error: Unauthorized for url: http://authentication-service:8443/api/user-management/user-info/
ERROR 2023-11-01 02:03:55,970 services Authentication failed due to: 401 Client Error: Unauthorized for url: http://authentication-service:8443/api/user-management/user-info/
ERROR 2023-11-01 02:04:01,075 services Authentication failed due to: 401 Client Error: Unauthorized for url: http://authentication-service:8443/api/user-management/user-info/
ERROR 2023-11-01 02:04:12,947 services Authentication failed due to: 401 Client Error: Unauthorized for url: http://authentication-service:8443/api/user-management/user-info/
ERROR 2023-11-01 03:04:49,821 services Authentication failed due to: 401 Client Error: Unauthorized for url: http://authentication-service:8443/api/user-management/user-info/
ERROR 2023-11-01 03:06:13,929 services Authentication failed due to: 401 Client Error: Unauthorized for url: http://authentication-service:8443/api/user-management/user-info/
ERROR 2023-11-01 03:31:11,745 services Authentication failed due to: 401 Client Error: Unauthorized for url: http://authentication-service:8443/api/user-management/user-info/
ERROR 2023-11-01 03:31:18,530 services Authentication failed due to: 401 Client Error: Unauthorized for url: http://authentication-service:8443/api/user-management/user-info/
ERROR 2023-11-01 04:05:39,663 services Authentication failed due to: 401 Client Error: Unauthorized for url: http://authentication-service:8443/api/user-management/user-info/
ERROR 2023-11-01 23:17:58,915 services Authentication failed due to: 401 Client Error: Unauthorized for url: http://authentication-service:8443/api/user-management/user-info/
ERROR 2023-11-02 00:32:54,101 services Authentication failed due to: 401 Client Error: Unauthorized for url: http://authentication-service:8443/api/user-management/user-info/
